Workbook

Sheet 操作說明
A1: LC8T 庫存健康度分析系統 - 操作說明 | C1: 📌 每月更新此欄號
C2: 最新銷貨月份欄號- 【銷貨數】工作表 | D2: ='銷貨數 (總數)(claude)'!A1 -> 16
A3: 📋 每月更新步驟 | C3: 目前最新月份 | D3: =IFERROR(TEXT(OFFSET('銷貨數 (總數)(claude)'!$E$3,0,操作說明!$D$2-5),"0"),"-") -> 202603
A5: STEP 1｜更新「在庫」工作表
A6: • 從 ERP 匯出最新庫存明細，從 Row5 開始貼上（覆蓋舊資料）
A7: • 欄位順序：A=品號 / B=品名 / C=單位成本 / D=庫存數量 / E=庫存金額
A8: • 注意：Row1~4 為標題，請勿覆蓋
A10: STEP 2｜更新「銷貨數(總數)」工作表（計算用，品名健康度來源）
A11: • 從 ERP 匯出各商品加總銷貨數量，從 Row3 貼上（覆蓋舊資料）
A12: • 欄位順序：A=事業別 / B=商品編號 / C=商品名稱 / D=商品單價 / E起=各月份銷量
A13: • 新月份往右新增一欄（Row2填月份代碼），資料從 Row3 起
A15: STEP 3｜更新月份參數格（每月唯一需手動的步驟）
A16: • 銷貨數(總數)新增新月份欄後，到「操作說明」工作表的 D2 格，將數字 +1
A17: • 例：目前 D2=27（AA欄=202602），新增202603後 → 改為 28
A18: • ✅ G欄(近6M) / M欄(近3M) / N欄(近12M) 自動更新，無需改任何公式
... A40: • 新品號出現「未對應」時，至「事業別定義」工作表新增對應規則

Sheet 學習商品
A1: ＃ | B1: 製品編號 | C1: 商品簡稱 | D1: 年齡 | E1: 製作單價 | F1: 售價 | G1: 原價％ | H1: 官網網址
A2: 7 | B2: 20250FE00 | C2: 巧虎雙語點讀圖鑑 | D2: 0.6-2歲 | E2: 676 | F2: 2399 | G2: =E2/F2 -> 0.28178408 | H2: https://store.benesse.com.tw/products/%E5%B7%A7%E8%99%8E%E9%9B%99%E8%AA%9E%E9%BB%9E%E8%AE%80%E5%9C%96%E9%91%91
A3: 1 | B3: 20240FA00 | C3: 寶寶生活好習慣套組 | D3: 1歲以上 | E3: 1565 | F3: 4299 | G3: =E3/F3 -> 0.36403815 | H3: https://store.benesse.com.tw/products/%E5%AF%B6%E5%AF%B6%E7%94%9F%E6%B4%BB%E5%A5%BD%E7%BF%92%E6%85%A3%E5%A5%97%E7%B5%84
A4: 6 | B4: 20250FD00 | C4: 寶寶語彙表達．智育學習套組 | D4: 1-2歲 | E4: 1593 | F4: 4900 | G4: =E4/F4 -> 0.32510204 | H4: https://store.benesse.com.tw/products/%E8%AA%9E%E5%BD%99%E8%A1%A8%E9%81%94%E6%99%BA%E8%82%B2%E5%AD%B8%E7%BF%92%E5%A5%97%E7%B5%84
A5: 3 | B5: 20230MY00 | C5: 和巧虎一起說英語Plus | D5: 1-3歲 | E5: 1642 | F5: 4800 | G5: =E5/F5 -> 0.34208333 | H5: https://store.benesse.com.tw/products/english-together%E5%92%8C%E5%B7%A7%E8%99%8E%E4%B8%80%E8%B5%B7%E8%AA%AA%E8%8B%B1%E8%AA%9Eplus
A6: 2 | B6: 20220MY00 | C6: 和巧虎一起說英語套組進階版 | D6: 3-7歲 | E6: 1492 | F6: 4500 | G6: =E6/F6 -> 0.33155556 | H6: https://store.benesse.com.tw/products/englishtogether-1
A7: 4 | B7: 20240FM00 | C7: 注音套組2.0 | D7: 3-6 歲 | E7: 987 | F7: 3200 | G7: =E7/F7 -> 0.3084375 | H7: https://store.benesse.com.tw/products/%E5%92%8C%E5%B7%A7%E8%99%8E%E4%B8%80%E8%B5%B7%E5%AD%B8%E6%B3%A8%E9%9F%B3%E6%8B%BC%E9%9F%B3%E5%A5%97%E7%B5%84
A8: 5 | B8: 20250FA00 | C8: 好情緒EQ X 品格人際套組 | D8: 3-5歲 | E8: 668 | F8: 2199 | G8: =E8/F8 -> 0.30377444 | H8: https://store.benesse.com.tw/products/%E5%A5%BD%E6%83%85%E7%B7%92eq%E5%93%81%E6%A0%BC%E4%BA%BA%E9%9A%9B%E5%A5%97%E7%B5%84
A9: 8 | B9: 20250FF00 | C9: 聰明左右腦 點讀大冒險套組 | D9: 3-6歲 | E9: 1194 | F9: 2999 | G9: =E9/F9 -> 0.39813271 | H9: https://store.benesse.com.tw/products/%E8%81%B0%E6%98%8E%E5%B7%A6%E5%8F%B3%E8%85%A6%E9%BB%9E%E8%AE%80%E5%A4%A7%E5%86%92%E9%9A%AA
A10: 9 | B10: 20250FG00 | C10: 和巧虎一起學數學套組 | D10: 3-6歲 | E10: 934 | F10: 3200 | G10: =E10/F10 -> 0.291875 | H10: https://store.benesse.com.tw/products/%E5%92%8C%E5%B7%A7%E8%99%8E%E4%B8%80%E8%B5%B7%E5%AD%B8%E6%95%B8%E5%AD%B8%E5%A5%97%E7%B5%84

Sheet 會議用記錄
A1: ＃ | B1: 製品編號 | C1: 商品簡稱
A2: 7 | B2: 20250FE00 | C2: 巧虎雙語點讀圖鑑
A3: 1 | B3: 20240FA00 | C3: 寶寶生活好習慣套組
A4: 6 | B4: 20250FD00 | C4: 寶寶語彙表達．智育學習套組
A5: 3 | B5: 20230MY00 | C5: 和巧虎一起說英語Plus
A6: 2 | B6: 20220MY00 | C6: 和巧虎一起說英語套組進階版
A7: 4 | B7: 20240FM00 | C7: 注音套組2.0
A8: 5 | B8: 20250FA00 | C8: 好情緒EQ X 品格人際套組
A9: 8 | B9: 20250FF00 | C9: 聰明左右腦 點讀大冒險套組
A10: 9 | B10: 20250FG00 | C10: 和巧虎一起學數學套組

Sheet 品名健康度
A1: 品名健康度分析 ｜ 全事業別 × 全品名 ｜ 近N月銷量：參照「操作說明!D2」欄號，每月只需更新該參數
A2: ⚡ 此工作表全欄位為動態公式，更新「在庫」及「銷貨數」工作表後，本表自動刷新。事業別歸屬請維護「事業別定義」工作表。
A3: 健康度說明：✅健康≤3M 🟡偏高3-6M 🟠警示6-12M 🔴滯銷風險>12M ⚠️有庫無銷=近6M零銷售 ｜ 消化月數=庫存÷月均銷量(近6M) ｜ 銷售來源：銷貨數(總數)工作表
A4: 事業別歸屬 | B4: 原始事業別 | C4: 商品編號 | D4: 商品名稱 | E4: 總庫存數量 | F4: 總庫存金額(NT$) | G4: 近12M銷量 | H4: 近6M銷量 | I4: 近3M銷量 | J4: 月均銷量 | K4: 消化月數 | L4: 健康度 | M4: 備注 | N4: 預估完售月
A5: =IFERROR(_xlfn.XLOOKUP(B5,事業別定義!A$2:A$9,事業別定義!B$2:B$9,IF(E5>0,"周邊商品","")),IF(E5>0,"周邊商品","")) -> 周邊商品 | B5: =IFERROR(_xlfn.XLOOKUP(C5,'銷貨數(claude)'!E:E,'銷貨數(claude)'!A:A,"周邊商品"),"周邊商品") -> 周邊商品 | C5: ='在庫(claude)'!A5 -> 20162C605 | D5: =IFERROR(_xlfn.XLOOKUP(C5,'在庫(claude)'!A$5:A$695,'在庫(claude)'!B$5:B$695,""),"") -> 1605月幼幼版彩色形狀建築師 | E5: =IFERROR(SUMIF('在庫(claude)'!A$5:A$695,C5,'在庫(claude)'!D$5:D$695),0) -> 6 | F5: =IFERROR(SUMIF('在庫(claude)'!A$5:A$695,C5,'在庫(claude)'!E$5:E$695),0) -> 353 | G5: =IFERROR(SUMPRODUCT(('銷貨數 (總數)(claude)'!$B$4:$B$1576=C5)*OFFSET('銷貨數 (總數)(claude)'!$E$4:$E$1576,0,操作說明!$D$2-16,1573,12)),0) -> 0 | H5: =IFERROR(SUMPRODUCT(('銷貨數 (總數)(claude)'!$B$4:$B$1576=C5)*OFFSET('銷貨數 (總數)(claude)'!$E$4:$E$1576,0,操作說明!$D$2-10,1573,6)),0) -> 0 | I5: =IFERROR(SUMPRODUCT(('銷貨數 (總數)(claude)'!$B$4:$B$1576=C5)*OFFSET('銷貨數 (總數)(claude)'!$E$4:$E$1576,0,操作說明!$D$2-7,1573,3)),0) -> 0 | J5: {=IFERROR(ROUND(H5/MAX(1,SUMPRODUCT(('銷貨數 (總數)(claude)'!$B$4:$B$1576=C5)*(OFFSET('銷貨數 (總數)(claude)'!$E$4:$E$1576,0,操作說明!$D$2-10,1573,6)>0))),1),0)} -> 0 | K5: =IFERROR(IF(J5=0,"-",ROUND(E5/J5,1)),"-") -> - | L5: =IFERROR(IF(E5=0,"無庫存",IF(J5=0,"滯銷(有庫無銷)",IF(E5/J5<=3,"健康",IF(E5/J5<=6,"偏高",IF(E5/J5<=12,"警示","滯銷風險"))))),"無庫存") -> 滯銷(有庫無銷) | M5: =IFERROR(IF(E5=0,"",IF(J5=0,"⚠️ 近6M零銷售，請確認是否列入促銷或處分",IF(E5/J5>24,"🔴 超過2年消化量，建議促銷/庫存處分",IF(E5/J5>12,"🔴 消化月數超過12個月，滯銷風險高",IF(E5/J5>6,"🟠 消化月數6-12個月，持續觀察",IF(E5/J5>3,"🟡 消化月數3-6個月，偏高注意","✅ 庫存健康")))))),"") -> ⚠️ 近6M零銷售，請確認是否列入促銷或處分 | N5: =IFERROR(IF(E5=0,"已售完",IF(J5=0,"無法預估",TEXT(EDATE(TODAY(),ROUND(E5/J5,0)),"YYYY/MM"))),"無法預估") -> 無法預估
A6: =IFERROR(_xlfn.XLOOKUP(B6,事業別定義!A$2:A$9,事業別定義!B$2:B$9,IF(E6>0,"周邊商品","")),IF(E6>0,"周邊商品","")) -> 周邊商品 | B6: =IFERROR(_xlfn.XLOOKUP(C6,'銷貨數(claude)'!E:E,'銷貨數(claude)'!A:A,"周邊商品"),"周邊商品") -> 巧連智商品 | C6: ='在庫(claude)'!A6 -> 2017AC109 | D6: =IFERROR(_xlfn.XLOOKUP(C6,'在庫(claude)'!A$5:A$695,'在庫(claude)'!B$5:B$695,""),"") -> 繪本-早安！起床了！ | E6: =IFERROR(SUMIF('在庫(claude)'!A$5:A$695,C6,'在庫(claude)'!D$5:D$695),0) -> 5 | F6: =IFERROR(SUMIF('在庫(claude)'!A$5:A$695,C6,'在庫(claude)'!E$5:E$695),0) -> 289 | G6: =IFERROR(SUMPRODUCT(('銷貨數 (總數)(claude)'!$B$4:$B$1576=C6)*OFFSET('銷貨數 (總數)(claude)'!$E$4:$E$1576,0,操作說明!$D$2-16,1573,12)),0) -> 39 | H6: =IFERROR(SUMPRODUCT(('銷貨數 (總數)(claude)'!$B$4:$B$1576=C6)*OFFSET('銷貨數 (總數)(claude)'!$E$4:$E$1576,0,操作說明!$D$2-10,1573,6)),0) -> 39 | I6: =IFERROR(SUMPRODUCT(('銷貨數 (總數)(claude)'!$B$4:$B$1576=C6)*OFFSET('銷貨數 (總數)(claude)'!$E$4:$E$1576,0,操作說明!$D$2-7,1573,3)),0) -> 10 | J6: {=IFERROR(ROUND(H6/MAX(1,SUMPRODUCT(('銷貨數 (總數)(claude)'!$B$4:$B$1576=C6)*(OFFSET('銷貨數 (總數)(claude)'!$E$4:$E$1576,0,操作說明!$D$2-10,1573,6)>0))),1),0)} -> 5.6 | K6: =IFERROR(IF(J6=0,"-",ROUND(E6/J6,1)),"-") -> 0.9 | L6: =IFERROR(IF(E6=0,"無庫存",IF(J6=0,"滯銷(有庫無銷)",IF(E6/J6<=3,"健康",IF(E6/J6<=6,"偏高",IF(E6/J6<=12,"警示","滯銷風險"))))),"無庫存") -> 健康 | M6: =IFERROR(IF(E6=0,"",IF(J6=0,"⚠️ 近6M零銷售，請確認是否列入促銷或處分",IF(E6/J6>24,"🔴 超過2年消化量，建議促銷/庫存處分",IF(E6/J6>12,"🔴 消化月數超過12個月，滯銷風險高",IF(E6/J6>6,"🟠 消化月數6-12個月，持續觀察",IF(E6/J6>3,"🟡 消化月數3-6個月，偏高注意","✅ 庫存健康")))))),"") -> ✅ 庫存健康 | N6: =IFERROR(IF(E6=0,"已售完",IF(J6=0,"無法預估",TEXT(EDATE(TODAY(),ROUND(E6/J6,0)),"YYYY/MM"))),"無法預估") -> 2026/06
A7: =IFERROR(_xlfn.XLOOKUP(B7,事業別定義!A$2:A$9,事業別定義!B$2:B$9,IF(E7>0,"周邊商品","")),IF(E7>0,"周邊商品","")) -> 周邊商品 | B7: =IFERROR(_xlfn.XLOOKUP(C7,'銷貨數(claude)'!E:E,'銷貨數(claude)'!A:A,"周邊商品"),"周邊商品") -> 周邊商品 | C7: ='在庫(claude)'!A7 -> 2017AC110 | D7: =IFERROR(_xlfn.XLOOKUP(C7,'在庫(claude)'!A$5:A$695,'在庫(claude)'!B$5:B$695,""),"") -> 繪本-這是什麼？身體圖鑑 | E7: =IFERROR(SUMIF('在庫(claude)'!A$5:A$695,C7,'在庫(claude)'!D$5:D$695),0) -> 183 | F7: =IFERROR(SUMIF('在庫(claude)'!A$5:A$695,C7,'在庫(claude)'!E$5:E$695),0) -> 6114 | G7: =IFERROR(SUMPRODUCT(('銷貨數 (總數)(claude)'!$B$4:$B$1576=C7)*OFFSET('銷貨數 (總數)(claude)'!$E$4:$E$1576,0,操作說明!$D$2-16,1573,12)),0) -> 0 | H7: =IFERROR(SUMPRODUCT(('銷貨數 (總數)(claude)'!$B$4:$B$1576=C7)*OFFSET('銷貨數 (總數)(claude)'!$E$4:$E$1576,0,操作說明!$D$2-10,1573,6)),0) -> 0 | I7: =IFERROR(SUMPRODUCT(('銷貨數 (總數)(claude)'!$B$4:$B$1576=C7)*OFFSET('銷貨數 (總數)(claude)'!$E$4:$E$1576,0,操作說明!$D$2-7,1573,3)),0) -> 0 | J7: {=IFERROR(ROUND(H7/MAX(1,SUMPRODUCT(('銷貨數 (總數)(claude)'!$B$4:$B$1576=C7)*(OFFSET('銷貨數 (總數)(claude)'!$E$4:$E$1576,0,操作說明!$D$2-10,1573,6)>0))),1),0)} -> 0 | K7: =IFERROR(IF(J7=0,"-",ROUND(E7/J7,1)),"-") -> - | L7: =IFERROR(IF(E7=0,"無庫存",IF(J7=0,"滯銷(有庫無銷)",IF(E7/J7<=3,"健康",IF(E7/J7<=6,"偏高",IF(E7/J7<=12,"警示","滯銷風險"))))),"無庫存") -> 滯銷(有庫無銷) | M7: =IFERROR(IF(E7=0,"",IF(J7=0,"⚠️ 近6M零銷售，請確認是否列入促銷或處分",IF(E7/J7>24,"🔴 超過2年消化量，建議促銷/庫存處分",IF(E7/J7>12,"🔴 消化月數超過12個月，滯銷風險高",IF(E7/J7>6,"🟠 消化月數6-12個月，持續觀察",IF(E7/J7>3,"🟡 消化月數3-6個月，偏高注意","✅ 庫存健康")))))),"") -> ⚠️ 近6M零銷售，請確認是否列入促銷或處分 | N7: =IFERROR(IF(E7=0,"已售完",IF(J7=0,"無法預估",TEXT(EDATE(TODAY(),ROUND(E7/J7,0)),"YYYY/MM"))),"無法預估") -> 無法預估
A8: =IFERROR(_xlfn.XLOOKUP(B8,事業別定義!A$2:A$9,事業別定義!B$2:B$9,IF(E8>0,"周邊商品","")),IF(E8>0,"周邊商品","")) -> 周邊商品 | B8: =IFERROR(_xlfn.XLOOKUP(C8,'銷貨數(claude)'!E:E,'銷貨數(claude)'!A:A,"周邊商品"),"周邊商品") -> 周邊商品 | C8: ='在庫(claude)'!A8 -> 2017AC111 | D8: =IFERROR(_xlfn.XLOOKUP(C8,'在庫(claude)'!A$5:A$695,'在庫(claude)'!B$5:B$695,""),"") -> 繪本-這是什麼？食物與生活用品 | E8: =IFERROR(SUMIF('在庫(claude)'!A$5:A$695,C8,'在庫(claude)'!D$5:D$695),0) -> 187 | F8: =IFERROR(SUMIF('在庫(claude)'!A$5:A$695,C8,'在庫(claude)'!E$5:E$695),0) -> 9023 | G8: =IFERROR(SUMPRODUCT(('銷貨數 (總數)(claude)'!$B$4:$B$1576=C8)*OFFSET('銷貨數 (總數)(claude)'!$E$4:$E$1576,0,操作說明!$D$2-16,1573,12)),0) -> 0 | H8: =IFERROR(SUMPRODUCT(('銷貨數 (總數)(claude)'!$B$4:$B$1576=C8)*OFFSET('銷貨數 (總數)(claude)'!$E$4:$E$1576,0,操作說明!$D$2-10,1573,6)),0) -> 0 | I8: =IFERROR(SUMPRODUCT(('銷貨數 (總數)(claude)'!$B$4:$B$1576=C8)*OFFSET('銷貨數 (總數)(claude)'!$E$4:$E$1576,0,操作說明!$D$2-7,1573,3)),0) -> 0 | J8: {=IFERROR(ROUND(H8/MAX(1,SUMPRODUCT(('銷貨數 (總數)(claude)'!$B$4:$B$1576=C8)*(OFFSET('銷貨數 (總數)(claude)'!$E$4:$E$1576,0,操作說明!$D$2-10,1573,6)>0))),1),0)} -> 0 | K8: =IFERROR(IF(J8=0,"-",ROUND(E8/J8,1)),"-") -> - | L8: =IFERROR(IF(E8=0,"無庫存",IF(J8=0,"滯銷(有庫無銷)",IF(E8/J8<=3,"健康",IF(E8/J8<=6,"偏高",IF(E8/J8<=12,"警示","滯銷風險"))))),"無庫存") -> 滯銷(有庫無銷) | M8: =IFERROR(IF(E8=0,"",IF(J8=0,"⚠️ 近6M零銷售，請確認是否列入促銷或處分",IF(E8/J8>24,"🔴 超過2年消化量，建議促銷/庫存處分",IF(E8/J8>12,"🔴 消化月數超過12個月，滯銷風險高",IF(E8/J8>6,"🟠 消化月數6-12個月，持續觀察",IF(E8/J8>3,"🟡 消化月數3-6個月，偏高注意","✅ 庫存健康")))))),"") -> ⚠️ 近6M零銷售，請確認是否列入促銷或處分 | N8: =IFERROR(IF(E8=0,"已售完",IF(J8=0,"無法預估",TEXT(EDATE(TODAY(),ROUND(E8/J8,0)),"YYYY/MM"))),"無法預估") -> 無法預估
A9: =IFERROR(_xlfn.XLOOKUP(B9,事業別定義!A$2:A$9,事業別定義!B$2:B$9,IF(E9>0,"周邊商品","")),IF(E9>0,"周邊商品","")) -> 周邊商品 | B9: =IFERROR(_xlfn.XLOOKUP(C9,'銷貨數(claude)'!E:E,'銷貨數(claude)'!A:A,"周邊商品"),"周邊商品") -> 周邊商品 | C9: ='在庫(claude)'!A9 -> 2017AC113 | D9: =IFERROR(_xlfn.XLOOKUP(C9,'在庫(claude)'!A$5:A$695,'在庫(claude)'!B$5:B$695,""),"") -> 繪本-我會大聲說有 | E9: =IFERROR(SUMIF('在庫(claude)'!A$5:A$695,C9,'在庫(claude)'!D$5:D$695),0) -> 64 | F9: =IFERROR(SUMIF('在庫(claude)'!A$5:A$695,C9,'在庫(claude)'!E$5:E$695),0) -> 2979 | G9: =IFERROR(SUMPRODUCT(('銷貨數 (總數)(claude)'!$B$4:$B$1576=C9)*OFFSET('銷貨數 (總數)(claude)'!$E$4:$E$1576,0,操作說明!$D$2-16,1573,12)),0) -> 0 | H9: =IFERROR(SUMPRODUCT(('銷貨數 (總數)(claude)'!$B$4:$B$1576=C9)*OFFSET('銷貨數 (總數)(claude)'!$E$4:$E$1576,0,操作說明!$D$2-10,1573,6)),0) -> 0 | I9: =IFERROR(SUMPRODUCT(('銷貨數 (總數)(claude)'!$B$4:$B$1576=C9)*OFFSET('銷貨數 (總數)(claude)'!$E$4:$E$1576,0,操作說明!$D$2-7,1573,3)),0) -> 0 | J9: {=IFERROR(ROUND(H9/MAX(1,SUMPRODUCT(('銷貨數 (總數)(claude)'!$B$4:$B$1576=C9)*(OFFSET('銷貨數 (總數)(claude)'!$E$4:$E$1576,0,操作說明!$D$2-10,1573,6)>0))),1),0)} -> 0 | K9: =IFERROR(IF(J9=0,"-",ROUND(E9/J9,1)),"-") -> - | L9: =IFERROR(IF(E9=0,"無庫存",IF(J9=0,"滯銷(有庫無銷)",IF(E9/J9<=3,"健康",IF(E9/J9<=6,"偏高",IF(E9/J9<=12,"警示","滯銷風險"))))),"無庫存") -> 滯銷(有庫無銷) | M9: =IFERROR(IF(E9=0,"",IF(J9=0,"⚠️ 近6M零銷售，請確認是否列入促銷或處分",IF(E9/J9>24,"🔴 超過2年消化量，建議促銷/庫存處分",IF(E9/J9>12,"🔴 消化月數超過12個月，滯銷風險高",IF(E9/J9>6,"🟠 消化月數6-12個月，持續觀察",IF(E9/J9>3,"🟡 消化月數3-6個月，偏高注意","✅ 庫存健康")))))),"") -> ⚠️ 近6M零銷售，請確認是否列入促銷或處分 | N9: =IFERROR(IF(E9=0,"已售完",IF(J9=0,"無法預估",TEXT(EDATE(TODAY(),ROUND(E9/J9,0)),"YYYY/MM"))),"無法預估") -> 無法預估
A10: =IFERROR(_xlfn.XLOOKUP(B10,事業別定義!A$2:A$9,事業別定義!B$2:B$9,IF(E10>0,"周邊商品","")),IF(E10>0,"周邊商品","")) -> 周邊商品 | B10: =IFERROR(_xlfn.XLOOKUP(C10,'銷貨數(claude)'!E:E,'銷貨數(claude)'!A:A,"周邊商品"),"周邊商品") -> 周邊商品 | C10: ='在庫(claude)'!A10 -> 2017AC121 | D10: =IFERROR(_xlfn.XLOOKUP(C10,'在庫(claude)'!A$5:A$695,'在庫(claude)'!B$5:B$695,""),"") -> 繪本-一起分享好開心 | E10: =IFERROR(SUMIF('在庫(claude)'!A$5:A$695,C10,'在庫(claude)'!D$5:D$695),0) -> 24 | F10: =IFERROR(SUMIF('在庫(claude)'!A$5:A$695,C10,'在庫(claude)'!E$5:E$695),0) -> 1258 | G10: =IFERROR(SUMPRODUCT(('銷貨數 (總數)(claude)'!$B$4:$B$1576=C10)*OFFSET('銷貨數 (總數)(claude)'!$E$4:$E$1576,0,操作說明!$D$2-16,1573,12)),0) -> 0 | H10: =IFERROR(SUMPRODUCT(('銷貨數 (總數)(claude)'!$B$4:$B$1576=C10)*OFFSET('銷貨數 (總數)(claude)'!$E$4:$E$1576,0,操作說明!$D$2-10,1573,6)),0) -> 0 | I10: =IFERROR(SUMPRODUCT(('銷貨數 (總數)(claude)'!$B$4:$B$1576=C10)*OFFSET('銷貨數 (總數)(claude)'!$E$4:$E$1576,0,操作說明!$D$2-7,1573,3)),0) -> 0 | J10: {=IFERROR(ROUND(H10/MAX(1,SUMPRODUCT(('銷貨數 (總數)(claude)'!$B$4:$B$1576=C10)*(OFFSET('銷貨數 (總數)(claude)'!$E$4:$E$1576,0,操作說明!$D$2-10,1573,6)>0))),1),0)} -> 0 | K10: =IFERROR(IF(J10=0,"-",ROUND(E10/J10,1)),"-") -> - | L10: =IFERROR(IF(E10=0,"無庫存",IF(J10=0,"滯銷(有庫無銷)",IF(E10/J10<=3,"健康",IF(E10/J10<=6,"偏高",IF(E10/J10<=12,"警示","滯銷風險"))))),"無庫存") -> 滯銷(有庫無銷) | M10: =IFERROR(IF(E10=0,"",IF(J10=0,"⚠️ 近6M零銷售，請確認是否列入促銷或處分",IF(E10/J10>24,"🔴 超過2年消化量，建議促銷/庫存處分",IF(E10/J10>12,"🔴 消化月數超過12個月，滯銷風險高",IF(E10/J10>6,"🟠 消化月數6-12個月，持續觀察",IF(E10/J10>3,"🟡 消化月數3-6個月，偏高注意","✅ 庫存健康")))))),"") -> ⚠️ 近6M零銷售，請確認是否列入促銷或處分 | N10: =IFERROR(IF(E10=0,"已售完",IF(J10=0,"無法預估",TEXT(EDATE(TODAY(),ROUND(E10/J10,0)),"YYYY/MM"))),"無法預估") -> 無法預估
A11: =IFERROR(_xlfn.XLOOKUP(B11,事業別定義!A$2:A$9,事業別定義!B$2:B$9,IF(E11>0,"周邊商品","")),IF(E11>0,"周邊商品","")) -> 周邊商品 | B11: =IFERROR(_xlfn.XLOOKUP(C11,'銷貨數(claude)'!E:E,'銷貨數(claude)'!A:A,"周邊商品"),"周邊商品") -> 周邊商品 | C11: ='在庫(claude)'!A11 -> 2017AC611 | D11: =IFERROR(_xlfn.XLOOKUP(C11,'在庫(claude)'!A$5:A$695,'在庫(claude)'!B$5:B$695,""),"") -> 11月齡寶寶推推樂 | E11: =IFERROR(SUMIF('在庫(claude)'!A$5:A$695,C11,'在庫(claude)'!D$5:D$695),0) -> 1 | F11: =IFERROR(SUMIF('在庫(claude)'!A$5:A$695,C11,'在庫(claude)'!E$5:E$695),0) -> 51 | G11: =IFERROR(SUMPRODUCT(('銷貨數 (總數)(claude)'!$B$4:$B$1576=C11)*OFFSET('銷貨數 (總數)(claude)'!$E$4:$E$1576,0,操作說明!$D$2-16,1573,12)),0) -> 0 | H11: =IFERROR(SUMPRODUCT(('銷貨數 (總數)(claude)'!$B$4:$B$1576=C11)*OFFSET('銷貨數 (總數)(claude)'!$E$4:$E$1576,0,操作說明!$D$2-10,1573,6)),0) -> 0 | I11: =IFERROR(SUMPRODUCT(('銷貨數 (總數)(claude)'!$B$4:$B$1576=C11)*OFFSET('銷貨數 (總數)(claude)'!$E$4:$E$1576,0,操作說明!$D$2-7,1573,3)),0) -> 0 | J11: {=IFERROR(ROUND(H11/MAX(1,SUMPRODUCT(('銷貨數 (總數)(claude)'!$B$4:$B$1576=C11)*(OFFSET('銷貨數 (總數)(claude)'!$E$4:$E$1576,0,操作說明!$D$2-10,1573,6)>0))),1),0)} -> 0 | K11: =IFERROR(IF(J11=0,"-",ROUND(E11/J11,1)),"-") -> - | L11: =IFERROR(IF(E11=0,"無庫存",IF(J11=0,"滯銷(有庫無銷)",IF(E11/J11<=3,"健康",IF(E11/J11<=6,"偏高",IF(E11/J11<=12,"警示","滯銷風險"))))),"無庫存") -> 滯銷(有庫無銷) | M11: =IFERROR(IF(E11=0,"",IF(J11=0,"⚠️ 近6M零銷售，請確認是否列入促銷或處分",IF(E11/J11>24,"🔴 超過2年消化量，建議促銷/庫存處分",IF(E11/J11>12,"🔴 消化月數超過12個月，滯銷風險高",IF(E11/J11>6,"🟠 消化月數6-12個月，持續觀察",IF(E11/J11>3,"🟡 消化月數3-6個月，偏高注意","✅ 庫存健康")))))),"") -> ⚠️ 近6M零銷售，請確認是否列入促銷或處分 | N11: =IFERROR(IF(E11=0,"已售完",IF(J11=0,"無法預估",TEXT(EDATE(TODAY(),ROUND(E11/J11,0)),"YYYY/MM"))),"無法預估") -> 無法預估
A12: =IFERROR(_xlfn.XLOOKUP(B12,事業別定義!A$2:A$9,事業別定義!B$2:B$9,IF(E12>0,"周邊商品","")),IF(E12>0,"周邊商品","")) -> 周邊商品 | B12: =IFERROR(_xlfn.XLOOKUP(C12,'銷貨數(claude)'!E:E,'銷貨數(claude)'!A:A,"周邊商品"),"周邊商品") -> 周邊商品 | C12: ='在庫(claude)'!A12 -> 20184C603 | D12: =IFERROR(_xlfn.XLOOKUP(C12,'在庫(claude)'!A$5:A$695,'在庫(claude)'!B$5:B$695,""),"") -> 桌遊-恐龍世界大挑戰 | E12: =IFERROR(SUMIF('在庫(claude)'!A$5:A$695,C12,'在庫(claude)'!D$5:D$695),0) -> 33 | F12: =IFERROR(SUMIF('在庫(claude)'!A$5:A$695,C12,'在庫(claude)'!E$5:E$695),0) -> 1516 | G12: =IFERROR(SUMPRODUCT(('銷貨數 (總數)(claude)'!$B$4:$B$1576=C12)*OFFSET('銷貨數 (總數)(claude)'!$E$4:$E$1576,0,操作說明!$D$2-16,1573,12)),0) -> 0 | H12: =IFERROR(SUMPRODUCT(('銷貨數 (總數)(claude)'!$B$4:$B$1576=C12)*OFFSET('銷貨數 (總數)(claude)'!$E$4:$E$1576,0,操作說明!$D$2-10,1573,6)),0) -> 0 | I12: =IFERROR(SUMPRODUCT(('銷貨數 (總數)(claude)'!$B$4:$B$1576=C12)*OFFSET('銷貨數 (總數)(claude)'!$E$4:$E$1576,0,操作說明!$D$2-7,1573,3)),0) -> 0 | J12: {=IFERROR(ROUND(H12/MAX(1,SUMPRODUCT(('銷貨數 (總數)(claude)'!$B$4:$B$1576=C12)*(OFFSET('銷貨數 (總數)(claude)'!$E$4:$E$1576,0,操作說明!$D$2-10,1573,6)>0))),1),0)} -> 0 | K12: =IFERROR(IF(J12=0,"-",ROUND(E12/J12,1)),"-") -> - | L12: =IFERROR(IF(E12=0,"無庫存",IF(J12=0,"滯銷(有庫無銷)",IF(E12/J12<=3,"健康",IF(E12/J12<=6,"偏高",IF(E12/J12<=12,"警示","滯銷風險"))))),"無庫存") -> 滯銷(有庫無銷) | M12: =IFERROR(IF(E12=0,"",IF(J12=0,"⚠️ 近6M零銷售，請確認是否列入促銷或處分",IF(E12/J12>24,"🔴 超過2年消化量，建議促銷/庫存處分",IF(E12/J12>12,"🔴 消化月數超過12個月，滯銷風險高",IF(E12/J12>6,"🟠 消化月數6-12個月，持續觀察",IF(E12/J12>3,"🟡 消化月數3-6個月，偏高注意","✅ 庫存健康")))))),"") -> ⚠️ 近6M零銷售，請確認是否列入促銷或處分 | N12: =IFERROR(IF(E12=0,"已售完",IF(J12=0,"無法預估",TEXT(EDATE(TODAY(),ROUND(E12/J12,0)),"YYYY/MM"))),"無法預估") -> 無法預估
A13: =IFERROR(_xlfn.XLOOKUP(B13,事業別定義!A$2:A$9,事業別定義!B$2:B$9,IF(E13>0,"周邊商品","")),IF(E13>0,"周邊商品","")) -> 周邊商品 | B13: =IFERROR(_xlfn.XLOOKUP(C13,'銷貨數(claude)'!E:E,'銷貨數(claude)'!A:A,"周邊商品"),"周邊商品") -> 巧連智商品 | C13: ='在庫(claude)'!A13 -> 2018AC812 | D13: =IFERROR(_xlfn.XLOOKUP(C13,'在庫(claude)'!A$5:A$695,'在庫(claude)'!B$5:B$695,""),"") -> 巧虎手偶 | E13: =IFERROR(SUMIF('在庫(claude)'!A$5:A$695,C13,'在庫(claude)'!D$5:D$695),0) -> 1528 | F13: =IFERROR(SUMIF('在庫(claude)'!A$5:A$695,C13,'在庫(claude)'!E$5:E$695),0) -> 112306 | G13: =IFERROR(SUMPRODUCT(('銷貨數 (總數)(claude)'!$B$4:$B$1576=C13)*OFFSET('銷貨數 (總數)(claude)'!$E$4:$E$1576,0,操作說明!$D$2-16,1573,12)),0) -> 657 | H13: =IFERROR(SUMPRODUCT(('銷貨數 (總數)(claude)'!$B$4:$B$1576=C13)*OFFSET('銷貨數 (總數)(claude)'!$E$4:$E$1576,0,操作說明!$D$2-10,1573,6)),0) -> 657 | I13: =IFERROR(SUMPRODUCT(('銷貨數 (總數)(claude)'!$B$4:$B$1576=C13)*OFFSET('銷貨數 (總數)(claude)'!$E$4:$E$1576,0,操作說明!$D$2-7,1573,3)),0) -> 360 | J13: {=IFERROR(ROUND(H13/MAX(1,SUMPRODUCT(('銷貨數 (總數)(claude)'!$B$4:$B$1576=C13)*(OFFSET('銷貨數 (總數)(claude)'!$E$4:$E$1576,0,操作說明!$D$2-10,1573,6)>0))),1),0)} -> 43.8 | K13: =IFERROR(IF(J13=0,"-",ROUND(E13/J13,1)),"-") -> 34.9 | L13: =IFERROR(IF(E13=0,"無庫存",IF(J13=0,"滯銷(有庫無銷)",IF(E13/J13<=3,"健康",IF(E13/J13<=6,"偏高",IF(E13/J13<=12,"警示","滯銷風險"))))),"無庫存") -> 滯銷風險 | M13: =IFERROR(IF(E13=0,"",IF(J13=0,"⚠️ 近6M零銷售，請確認是否列入促銷或處分",IF(E13/J13>24,"🔴 超過2年消化量，建議促銷/庫存處分",IF(E13/J13>12,"🔴 消化月數超過12個月，滯銷風險高",IF(E13/J13>6,"🟠 消化月數6-12個月，持續觀察",IF(E13/J13>3,"🟡 消化月數3-6個月，偏高注意","✅ 庫存健康")))))),"") -> 🔴 超過2年消化量，建議促銷/庫存處分 | N13: =IFERROR(IF(E13=0,"已售完",IF(J13=0,"無法預估",TEXT(EDATE(TODAY(),ROUND(E13/J13,0)),"YYYY/MM"))),"無法預估") -> 2029/04
A14: =IFERROR(_xlfn.XLOOKUP(B14,事業別定義!A$2:A$9,事業別定義!B$2:B$9,IF(E14>0,"周邊商品","")),IF(E14>0,"周邊商品","")) -> 周邊商品 | B14: =IFERROR(_xlfn.XLOOKUP(C14,'銷貨數(claude)'!E:E,'銷貨數(claude)'!A:A,"周邊商品"),"周邊商品") -> 巧連智商品 | C14: ='在庫(claude)'!A14 -> 2018AC812-L | D14: =IFERROR(_xlfn.XLOOKUP(C14,'在庫(claude)'!A$5:A$695,'在庫(claude)'!B$5:B$695,""),"") -> 巧虎手偶說明信 | E14: =IFERROR(SUMIF('在庫(claude)'!A$5:A$695,C14,'在庫(claude)'!D$5:D$695),0) -> 1840 | F14: =IFERROR(SUMIF('在庫(claude)'!A$5:A$695,C14,'在庫(claude)'!E$5:E$695),0) -> 0 | G14: =IFERROR(SUMPRODUCT(('銷貨數 (總數)(claude)'!$B$4:$B$1576=C14)*OFFSET('銷貨數 (總數)(claude)'!$E$4:$E$1576,0,操作說明!$D$2-16,1573,12)),0) -> 1 | H14: =IFERROR(SUMPRODUCT(('銷貨數 (總數)(claude)'!$B$4:$B$1576=C14)*OFFSET('銷貨數 (總數)(claude)'!$E$4:$E$1576,0,操作說明!$D$2-10,1573,6)),0) -> 1 | I14: =IFERROR(SUMPRODUCT(('銷貨數 (總數)(claude)'!$B$4:$B$1576=C14)*OFFSET('銷貨數 (總數)(claude)'!$E$4:$E$1576,0,操作說明!$D$2-7,1573,3)),0) -> 1 | J14: {=IFERROR(ROUND(H14/MAX(1,SUMPRODUCT(('銷貨數 (總數)(claude)'!$B$4:$B$1576=C14)*(OFFSET('銷貨數 (總數)(claude)'!$E$4:$E$1576,0,操作說明!$D$2-10,1573,6)>0))),1),0)} -> 1 | K14: =IFERROR(IF(J14=0,"-",ROUND(E14/J14,1)),"-") -> 1840 | L14: =IFERROR(IF(E14=0,"無庫存",IF(J14=0,"滯銷(有庫無銷)",IF(E14/J14<=3,"健康",IF(E14/J14<=6,"偏高",IF(E14/J14<=12,"警示","滯銷風險"))))),"無庫存") -> 滯銷風險 | M14: =IFERROR(IF(E14=0,"",IF(J14=0,"⚠️ 近6M零銷售，請確認是否列入促銷或處分",IF(E14/J14>24,"🔴 超過2年消化量，建議促銷/庫存處分",IF(E14/J14>12,"🔴 消化月數超過12個月，滯銷風險高",IF(E14/J14>6,"🟠 消化月數6-12個月，持續觀察",IF(E14/J14>3,"🟡 消化月數3-6個月，偏高注意","✅ 庫存健康")))))),"") -> 🔴 超過2年消化量，建議促銷/庫存處分 | N14: =IFERROR(IF(E14=0,"已售完",IF(J14=0,"無法預估",TEXT(EDATE(TODAY(),ROUND(E14/J14,0)),"YYYY/MM"))),"無法預估") -> 2179/09
A15: =IFERROR(_xlfn.XLOOKUP(B15,事業別定義!A$2:A$9,事業別定義!B$2:B$9,IF(E15>0,"周邊商品","")),IF(E15>0,"周邊商品","")) -> 周邊商品 | B15: =IFERROR(_xlfn.XLOOKUP(C15,'銷貨數(claude)'!E:E,'銷貨數(claude)'!A:A,"周邊商品"),"周邊商品") -> 周邊商品 | C15: ='在庫(claude)'!A15 -> 20191C601 | D15: =IFERROR(_xlfn.XLOOKUP(C15,'在庫(claude)'!A$5:A$695,'在庫(claude)'!B$5:B$695,""),"") -> 2001月號寶寶版生活語彙圖卡組 | E15: =IFERROR(SUMIF('在庫(claude)'!A$5:A$695,C15,'在庫(claude)'!D$5:D$695),0) -> 233 | F15: =IFERROR(SUMIF('在庫(claude)'!A$5:A$695,C15,'在庫(claude)'!E$5:E$695),0) -> 6866 | G15: =IFERROR(SUMPRODUCT(('銷貨數 (總數)(claude)'!$B$4:$B$1576=C15)*OFFSET('銷貨數 (總數)(claude)'!$E$4:$E$1576,0,操作說明!$D$2-16,1573,12)),0) -> 0 | H15: =IFERROR(SUMPRODUCT(('銷貨數 (總數)(claude)'!$B$4:$B$1576=C15)*OFFSET('銷貨數 (總數)(claude)'!$E$4:$E$1576,0,操作說明!$D$2-10,1573,6)),0) -> 0 | I15: =IFERROR(SUMPRODUCT(('銷貨數 (總數)(claude)'!$B$4:$B$1576=C15)*OFFSET('銷貨數 (總數)(claude)'!$E$4:$E$1576,0,操作說明!$D$2-7,1573,3)),0) -> 0 | J15: {=IFERROR(ROUND(H15/MAX(1,SUMPRODUCT(('銷貨數 (總數)(claude)'!$B$4:$B$1576=C15)*(OFFSET('銷貨數 (總數)(claude)'!$E$4:$E$1576,0,操作說明!$D$2-10,1573,6)>0))),1),0)} -> 0 | K15: =IFERROR(IF(J15=0,"-",ROUND(E15/J15,1)),"-") -> - | L15: =IFERROR(IF(E15=0,"無庫存",IF(J15=0,"滯銷(有庫無銷)",IF(E15/J15<=3,"健康",IF(E15/J15<=6,"偏高",IF(E15/J15<=12,"警示","滯銷風險"))))),"無庫存") -> 滯銷(有庫無銷) | M15: =IFERROR(IF(E15=0,"",IF(J15=0,"⚠️ 近6M零銷售，請確認是否列入促銷或處分",IF(E15/J15>24,"🔴 超過2年消化量，建議促銷/庫存處分",IF(E15/J15>12,"🔴 消化月數超過12個月，滯銷風險高",IF(E15/J15>6,"🟠 消化月數6-12個月，持續觀察",IF(E15/J15>3,"🟡 消化月數3-6個月，偏高注意","✅ 庫存健康")))))),"") -> ⚠️ 近6M零銷售，請確認是否列入促銷或處分 | N15: =IFERROR(IF(E15=0,"已售完",IF(J15=0,"無法預估",TEXT(EDATE(TODAY(),ROUND(E15/J15,0)),"YYYY/MM"))),"無法預估") -> 無法預估
A16: =IFERROR(_xlfn.XLOOKUP(B16,事業別定義!A$2:A$9,事業別定義!B$2:B$9,IF(E16>0,"周邊商品","")),IF(E16>0,"周邊商品","")) -> 周邊商品 | B16: =IFERROR(_xlfn.XLOOKUP(C16,'銷貨數(claude)'!E:E,'銷貨數(claude)'!A:A,"周邊商品"),"周邊商品") -> 巧連智商品 | C16: ='在庫(claude)'!A16 -> 20191C710 | D16: =IFERROR(_xlfn.XLOOKUP(C16,'在庫(claude)'!A$5:A$695,'在庫(claude)'!B$5:B$695,""),"") -> 1910月號寶寶版交通工具拼圖書 | E16: =IFERROR(SUMIF('在庫(claude)'!A$5:A$695,C16,'在庫(claude)'!D$5:D$695),0) -> 107 | F16: =IFERROR(SUMIF('在庫(claude)'!A$5:A$695,C16,'在庫(claude)'!E$5:E$695),0) -> 6371 | G16: =IFERROR(SUMPRODUCT(('銷貨數 (總數)(claude)'!$B$4:$B$1576=C16)*OFFSET('銷貨數 (總數)(claude)'!$E$4:$E$1576,0,操作說明!$D$2-16,1573,12)),0) -> 106 | H16: =IFERROR(SUMPRODUCT(('銷貨數 (總數)(claude)'!$B$4:$B$1576=C16)*OFFSET('銷貨數 (總數)(claude)'!$E$4:$E$1576,0,操作說明!$D$2-10,1573,6)),0) -> 50 | I16: =IFERROR(SUMPRODUCT(('銷貨數 (總數)(claude)'!$B$4:$B$1576=C16)*OFFSET('銷貨數 (總數)(claude)'!$E$4:$E$1576,0,操作說明!$D$2-7,1573,3)),0) -> 22 | J16: {=IFERROR(ROUND(H16/MAX(1,SUMPRODUCT(('銷貨數 (總數)(claude)'!$B$4:$B$1576=C16)*(OFFSET('銷貨數 (總數)(claude)'!$E$4:$E$1576,0,操作說明!$D$2-10,1573,6)>0))),1),0)} -> 8.3 | K16: =IFERROR(IF(J16=0,"-",ROUND(E16/J16,1)),"-") -> 12.9 | L16: =IFERROR(IF(E16=0,"無庫存",IF(J16=0,"滯銷(有庫無銷)",IF(E16/J16<=3,"健康",IF(E16/J16<=6,"偏高",IF(E16/J16<=12,"警示","滯銷風險"))))),"無庫存") -> 滯銷風險 | M16: =IFERROR(IF(E16=0,"",IF(J16=0,"⚠️ 近6M零銷售，請確認是否列入促銷或處分",IF(E16/J16>24,"🔴 超過2年消化量，建議促銷/庫存處分",IF(E16/J16>12,"🔴 消化月數超過12個月，滯銷風險高",IF(E16/J16>6,"🟠 消化月數6-12個月，持續觀察",IF(E16/J16>3,"🟡 消化月數3-6個月，偏高注意","✅ 庫存健康")))))),"") -> 🔴 消化月數超過12個月，滯銷風險高 | N16: =IFERROR(IF(E16=0,"已售完",IF(J16=0,"無法預估",TEXT(EDATE(TODAY(),ROUND(E16/J16,0)),"YYYY/MM"))),"無法預估") -> 2027/06
... A740: =IFERROR(_xlfn.XLOOKUP(B740,事業別定義!A$2:A$9,事業別定義!B$2:B$9,IF(E740>0,"周邊商品","")),IF(E740>0,"周邊商品","")) -> 周邊商品 | B740: =IFERROR(_xlfn.XLOOKUP(C740,'銷貨數(claude)'!E:E,'銷貨數(claude)'!A:A,"周邊商品"),"周邊商品") -> 周邊商品 | C740: ='在庫(claude)'!A740 -> 0 | D740: =IFERROR(_xlfn.XLOOKUP(C740,'在庫(claude)'!A$5:A$695,'在庫(claude)'!B$5:B$695,""),"") -> 0 | E740: =IFERROR(SUMIF('在庫(claude)'!A$5:A$695,C740,'在庫(claude)'!D$5:D$695),0) -> 0 | F740: =IFERROR(SUMIF('在庫(claude)'!A$5:A$695,C740,'在庫(claude)'!E$5:E$695),0) -> 0 | G740: =IFERROR(SUMPRODUCT(('銷貨數 (總數)(claude)'!$B$4:$B$1576=C740)*OFFSET('銷貨數 (總數)(claude)'!$E$4:$E$1576,0,操作說明!$D$2-16,1573,12)),0) -> 0 | H740: =IFERROR(SUMPRODUCT(('銷貨數 (總數)(claude)'!$B$4:$B$1576=C740)*OFFSET('銷貨數 (總數)(claude)'!$E$4:$E$1576,0,操作說明!$D$2-10,1573,6)),0) -> 0 | I740: =IFERROR(SUMPRODUCT(('銷貨數 (總數)(claude)'!$B$4:$B$1576=C740)*OFFSET('銷貨數 (總數)(claude)'!$E$4:$E$1576,0,操作說明!$D$2-7,1573,3)),0) -> 0 | J740: {=IFERROR(ROUND(H740/MAX(1,SUMPRODUCT(('銷貨數 (總數)(claude)'!$B$4:$B$1576=C740)*(OFFSET('銷貨數 (總數)(claude)'!$E$4:$E$1576,0,操作說明!$D$2-10,1573,6)>0))),1),0)} -> 0 | K740: =IFERROR(IF(J740=0,"-",ROUND(E740/J740,1)),"-") -> - | L740: =IFERROR(IF(E740=0,"無庫存",IF(J740=0,"滯銷(有庫無銷)",IF(E740/J740<=3,"健康",IF(E740/J740<=6,"偏高",IF(E740/J740<=12,"警示","滯銷風險"))))),"無庫存") -> 無庫存 | M740: =IFERROR(IF(E740=0,"",IF(J740=0,"⚠️ 近6M零銷售，請確認是否列入促銷或處分",IF(E740/J740>24,"🔴 超過2年消化量，建議促銷/庫存處分",IF(E740/J740>12,"🔴 消化月數超過12個月，滯銷風險高",IF(E740/J740>6,"🟠 消化月數6-12個月，持續觀察",IF(E740/J740>3,"🟡 消化月數3-6個月，偏高注意","✅ 庫存健康")))))),"") | N740: =IFERROR(IF(E740=0,"已售完",IF(J740=0,"無法預估",TEXT(EDATE(TODAY(),ROUND(E740/J740,0)),"YYYY/MM"))),"無法預估") -> 已售完

Sheet 事業別健康度
A1: 事業別健康度彙總 ｜ 全事業別概觀（巧連智商品＋舞台劇已歸入周邊商品）
A2: ⚡ 此工作表全欄位為動態公式，來源為「品名健康度」工作表，自動彙總。月均銷量分近3M/6M/12M三個基準。
A3: ⚠️ 「未對應」事業別=在庫有品號但銷貨數無對應紀錄，請更新「事業別定義」工作表後刷新。
A4: 事業別歸屬 | B4: 分析品項數 | C4: 有庫存品項 | D4: ✅健康 | E4: 🟡偏高 | F4: 🟠警示 | G4: 🔴滯銷風險 | H4: ⚠️有庫無銷 | I4: 總庫存金額(NT$) | J4: 近6M月均銷量合計 | K4: 近3M月均銷量合計 | L4: 近12M月均銷量合計 | M4: 滯銷金額(NT$) | N4: 滯銷金額佔比 | O4: 風險評估
A5: 學習商品 | B5: =COUNTIFS(品名健康度!A$5:A$740,A5,品名健康度!L$5:L$740,"<>") -> 18 | C5: =COUNTIFS(品名健康度!A$5:A$740,A5,品名健康度!L$5:L$740,"<>無庫存",品名健康度!L$5:L$740,"<>") -> 18 | D5: =COUNTIFS(品名健康度!A$5:A$740,A5,品名健康度!L$5:L$740,"健康") -> 0 | E5: =COUNTIFS(品名健康度!A$5:A$740,A5,品名健康度!L$5:L$740,"偏高") -> 3 | F5: =COUNTIFS(品名健康度!A$5:A$740,A5,品名健康度!L$5:L$740,"警示") -> 2 | G5: =COUNTIFS(品名健康度!A$5:A$740,A5,品名健康度!L$5:L$740,"滯銷風險") -> 12 | H5: =COUNTIFS(品名健康度!A$5:A$740,A5,品名健康度!L$5:L$740,"滯銷(有庫無銷)") -> 1 | I5: =SUMIFS(品名健康度!F$5:F$740,品名健康度!A$5:A$740,A5) -> 33368315 | J5: =ROUND(SUMIFS(品名健康度!J$5:J$740,品名健康度!A$5:A$740,A5),1) -> 3042.9 | K5: =IFERROR(ROUND(SUMIFS(品名健康度!I$5:I$740,品名健康度!A$5:A$740,A5)/3,1),0) -> 2121 | L5: =IFERROR(ROUND(SUMIFS(品名健康度!G$5:G$740,品名健康度!A$5:A$740,A5)/12,1),0) -> 1398.7 | M5: =SUMIFS(品名健康度!F$5:F$740,品名健康度!A$5:A$740,A5,品名健康度!L$5:L$740,"滯銷風險")+SUMIFS(品名健康度!F$5:F$740,品名健康度!A$5:A$740,A5,品名健康度!L$5:L$740,"滯銷(有庫無銷)") -> 21797253 | N5: =IFERROR(ROUND(M5/I5*100,1),"-") -> 65.3 | O5: =IFERROR(IF(G5+H5=0,"✅ 良好",IF((G5+H5)/C5>0.5,"🔴 高風險",IF((G5+H5)/C5>0.25,"🟠 注意","🟡 偏高"))),"✅ 良好") -> 🔴 高風險
A6: 周邊商品 | B6: =COUNTIFS(品名健康度!A$5:A$740,A6,品名健康度!L$5:L$740,"<>") -> 699 | C6: =COUNTIFS(品名健康度!A$5:A$740,A6,品名健康度!L$5:L$740,"<>無庫存",品名健康度!L$5:L$740,"<>") -> 647 | D6: =COUNTIFS(品名健康度!A$5:A$740,A6,品名健康度!L$5:L$740,"健康") -> 33 | E6: =COUNTIFS(品名健康度!A$5:A$740,A6,品名健康度!L$5:L$740,"偏高") -> 19 | F6: =COUNTIFS(品名健康度!A$5:A$740,A6,品名健康度!L$5:L$740,"警示") -> 31 | G6: =COUNTIFS(品名健康度!A$5:A$740,A6,品名健康度!L$5:L$740,"滯銷風險") -> 114 | H6: =COUNTIFS(品名健康度!A$5:A$740,A6,品名健康度!L$5:L$740,"滯銷(有庫無銷)") -> 450 | I6: =SUMIFS(品名健康度!F$5:F$740,品名健康度!A$5:A$740,A6) -> 21771129 | J6: =ROUND(SUMIFS(品名健康度!J$5:J$740,品名健康度!A$5:A$740,A6),1) -> 4516.9 | K6: =IFERROR(ROUND(SUMIFS(品名健康度!I$5:I$740,品名健康度!A$5:A$740,A6)/3,1),0) -> 5036.3 | L6: =IFERROR(ROUND(SUMIFS(品名健康度!G$5:G$740,品名健康度!A$5:A$740,A6)/12,1),0) -> 3803.3 | M6: =SUMIFS(品名健康度!F$5:F$740,品名健康度!A$5:A$740,A6,品名健康度!L$5:L$740,"滯銷風險")+SUMIFS(品名健康度!F$5:F$740,品名健康度!A$5:A$740,A6,品名健康度!L$5:L$740,"滯銷(有庫無銷)") -> 19732999 | N6: =IFERROR(ROUND(M6/I6*100,1),"-") -> 90.6 | O6: =IFERROR(IF(G6+H6=0,"✅ 良好",IF((G6+H6)/C6>0.5,"🔴 高風險",IF((G6+H6)/C6>0.25,"🟠 注意","🟡 偏高"))),"✅ 良好") -> 🔴 高風險
A7: Mirafeel | B7: =COUNTIFS(品名健康度!A$5:A$740,A7,品名健康度!L$5:L$740,"<>") -> 17 | C7: =COUNTIFS(品名健康度!A$5:A$740,A7,品名健康度!L$5:L$740,"<>無庫存",品名健康度!L$5:L$740,"<>") -> 17 | D7: =COUNTIFS(品名健康度!A$5:A$740,A7,品名健康度!L$5:L$740,"健康") -> 2 | E7: =COUNTIFS(品名健康度!A$5:A$740,A7,品名健康度!L$5:L$740,"偏高") -> 6 | F7: =COUNTIFS(品名健康度!A$5:A$740,A7,品名健康度!L$5:L$740,"警示") -> 2 | G7: =COUNTIFS(品名健康度!A$5:A$740,A7,品名健康度!L$5:L$740,"滯銷風險") -> 7 | H7: =COUNTIFS(品名健康度!A$5:A$740,A7,品名健康度!L$5:L$740,"滯銷(有庫無銷)") -> 0 | I7: =SUMIFS(品名健康度!F$5:F$740,品名健康度!A$5:A$740,A7) -> 241072 | J7: =ROUND(SUMIFS(品名健康度!J$5:J$740,品名健康度!A$5:A$740,A7),1) -> 143.4 | K7: =IFERROR(ROUND(SUMIFS(品名健康度!I$5:I$740,品名健康度!A$5:A$740,A7)/3,1),0) -> 185 | L7: =IFERROR(ROUND(SUMIFS(品名健康度!G$5:G$740,品名健康度!A$5:A$740,A7)/12,1),0) -> 186.8 | M7: =SUMIFS(品名健康度!F$5:F$740,品名健康度!A$5:A$740,A7,品名健康度!L$5:L$740,"滯銷風險")+SUMIFS(品名健康度!F$5:F$740,品名健康度!A$5:A$740,A7,品名健康度!L$5:L$740,"滯銷(有庫無銷)") -> 88686 | N7: =IFERROR(ROUND(M7/I7*100,1),"-") -> 36.8 | O7: =IFERROR(IF(G7+H7=0,"✅ 良好",IF((G7+H7)/C7>0.5,"🔴 高風險",IF((G7+H7)/C7>0.25,"🟠 注意","🟡 偏高"))),"✅ 良好") -> 🟠 注意
A8: 共通 | B8: =COUNTIFS(品名健康度!A$5:A$740,A8,品名健康度!L$5:L$740,"<>") -> 2 | C8: =COUNTIFS(品名健康度!A$5:A$740,A8,品名健康度!L$5:L$740,"<>無庫存",品名健康度!L$5:L$740,"<>") -> 2 | D8: =COUNTIFS(品名健康度!A$5:A$740,A8,品名健康度!L$5:L$740,"健康") -> 0 | E8: =COUNTIFS(品名健康度!A$5:A$740,A8,品名健康度!L$5:L$740,"偏高") -> 0 | F8: =COUNTIFS(品名健康度!A$5:A$740,A8,品名健康度!L$5:L$740,"警示") -> 0 | G8: =COUNTIFS(品名健康度!A$5:A$740,A8,品名健康度!L$5:L$740,"滯銷風險") -> 2 | H8: =COUNTIFS(品名健康度!A$5:A$740,A8,品名健康度!L$5:L$740,"滯銷(有庫無銷)") -> 0 | I8: =SUMIFS(品名健康度!F$5:F$740,品名健康度!A$5:A$740,A8) -> 31354 | J8: =ROUND(SUMIFS(品名健康度!J$5:J$740,品名健康度!A$5:A$740,A8),1) -> 173.2 | K8: =IFERROR(ROUND(SUMIFS(品名健康度!I$5:I$740,品名健康度!A$5:A$740,A8)/3,1),0) -> 154 | L8: =IFERROR(ROUND(SUMIFS(品名健康度!G$5:G$740,品名健康度!A$5:A$740,A8)/12,1),0) -> 55.2 | M8: =SUMIFS(品名健康度!F$5:F$740,品名健康度!A$5:A$740,A8,品名健康度!L$5:L$740,"滯銷風險")+SUMIFS(品名健康度!F$5:F$740,品名健康度!A$5:A$740,A8,品名健康度!L$5:L$740,"滯銷(有庫無銷)") -> 31354 | N8: =IFERROR(ROUND(M8/I8*100,1),"-") -> 100 | O8: =IFERROR(IF(G8+H8=0,"✅ 良好",IF((G8+H8)/C8>0.5,"🔴 高風險",IF((G8+H8)/C8>0.25,"🟠 注意","🟡 偏高"))),"✅ 良好") -> 🔴 高風險
A9: 其他 | B9: =COUNTIFS(品名健康度!A$5:A$740,A9,品名健康度!L$5:L$740,"<>") -> 0 | C9: =COUNTIFS(品名健康度!A$5:A$740,A9,品名健康度!L$5:L$740,"<>無庫存",品名健康度!L$5:L$740,"<>") -> 0 | D9: =COUNTIFS(品名健康度!A$5:A$740,A9,品名健康度!L$5:L$740,"健康") -> 0 | E9: =COUNTIFS(品名健康度!A$5:A$740,A9,品名健康度!L$5:L$740,"偏高") -> 0 | F9: =COUNTIFS(品名健康度!A$5:A$740,A9,品名健康度!L$5:L$740,"警示") -> 0 | G9: =COUNTIFS(品名健康度!A$5:A$740,A9,品名健康度!L$5:L$740,"滯銷風險") -> 0 | H9: =COUNTIFS(品名健康度!A$5:A$740,A9,品名健康度!L$5:L$740,"滯銷(有庫無銷)") -> 0 | I9: =SUMIFS(品名健康度!F$5:F$740,品名健康度!A$5:A$740,A9) -> 0 | J9: =ROUND(SUMIFS(品名健康度!J$5:J$740,品名健康度!A$5:A$740,A9),1) -> 0 | K9: =IFERROR(ROUND(SUMIFS(品名健康度!I$5:I$740,品名健康度!A$5:A$740,A9)/3,1),0) -> 0 | L9: =IFERROR(ROUND(SUMIFS(品名健康度!G$5:G$740,品名健康度!A$5:A$740,A9)/12,1),0) -> 0 | M9: =SUMIFS(品名健康度!F$5:F$740,品名健康度!A$5:A$740,A9,品名健康度!L$5:L$740,"滯銷風險")+SUMIFS(品名健康度!F$5:F$740,品名健康度!A$5:A$740,A9,品名健康度!L$5:L$740,"滯銷(有庫無銷)") -> 0 | N9: =IFERROR(ROUND(M9/I9*100,1),"-") -> - | O9: =IFERROR(IF(G9+H9=0,"✅ 良好",IF((G9+H9)/C9>0.5,"🔴 高風險",IF((G9+H9)/C9>0.25,"🟠 注意","🟡 偏高"))),"✅ 良好") -> ✅ 良好
A10: 未對應 | B10: =COUNTIFS(品名健康度!A$5:A$740,A10,品名健康度!L$5:L$740,"<>") -> 0 | C10: =COUNTIFS(品名健康度!A$5:A$740,A10,品名健康度!L$5:L$740,"<>無庫存",品名健康度!L$5:L$740,"<>") -> 0 | D10: =COUNTIFS(品名健康度!A$5:A$740,A10,品名健康度!L$5:L$740,"健康") -> 0 | E10: =COUNTIFS(品名健康度!A$5:A$740,A10,品名健康度!L$5:L$740,"偏高") -> 0 | F10: =COUNTIFS(品名健康度!A$5:A$740,A10,品名健康度!L$5:L$740,"警示") -> 0 | G10: =COUNTIFS(品名健康度!A$5:A$740,A10,品名健康度!L$5:L$740,"滯銷風險") -> 0 | H10: =COUNTIFS(品名健康度!A$5:A$740,A10,品名健康度!L$5:L$740,"滯銷(有庫無銷)") -> 0 | I10: =SUMIFS(品名健康度!F$5:F$740,品名健康度!A$5:A$740,A10) -> 0 | J10: =ROUND(SUMIFS(品名健康度!J$5:J$740,品名健康度!A$5:A$740,A10),1) -> 0 | K10: =IFERROR(ROUND(SUMIFS(品名健康度!I$5:I$740,品名健康度!A$5:A$740,A10)/3,1),0) -> 0 | L10: =IFERROR(ROUND(SUMIFS(品名健康度!G$5:G$740,品名健康度!A$5:A$740,A10)/12,1),0) -> 0 | M10: =SUMIFS(品名健康度!F$5:F$740,品名健康度!A$5:A$740,A10,品名健康度!L$5:L$740,"滯銷風險")+SUMIFS(品名健康度!F$5:F$740,品名健康度!A$5:A$740,A10,品名健康度!L$5:L$740,"滯銷(有庫無銷)") -> 0 | N10: =IFERROR(ROUND(M10/I10*100,1),"-") -> - | O10: =IFERROR(IF(G10+H10=0,"✅ 良好",IF((G10+H10)/C10>0.5,"🔴 高風險",IF((G10+H10)/C10>0.25,"🟠 注意","🟡 偏高"))),"✅ 良好") -> ✅ 良好
A11: 合計 | B11: =SUM(B5:B10) -> 736 | C11: =SUM(C5:C10) -> 684 | D11: =SUM(D5:D10) -> 35 | E11: =SUM(E5:E10) -> 28 | F11: =SUM(F5:F10) -> 35 | G11: =SUM(G5:G10) -> 135 | H11: =SUM(H5:H10) -> 451 | I11: =SUM(I5:I10) -> 55411870 | J11: =ROUND(SUM(J5:J10),1) -> 7876.4 | K11: =ROUND(SUM(K5:K10),1) -> 7496.3 | L11: =ROUND(SUM(L5:L10),1) -> 5444 | M11: =SUM(M5:M10) -> 41650292 | N11: =IFERROR(ROUND(M11/I11*100,1),"-") -> 75.2
A12: ＊ 周邊商品 包含：周邊商品（原）＋ 巧連智商品 ＋ 舞台劇

Sheet 事業別定義
A1: 事業別 | B1: FY25事業別歸屬
A2: 學習商品 | B2: =A2 -> 學習商品
A3: Mirafeel | B3: =A3 -> Mirafeel
A4: 巧連智商品 | B4: 周邊商品
A5: 共通 | B5: =A5 -> 共通
A6: 其他 | B6: =A6 -> 其他
A7: 周邊商品 | B7: =A7 -> 周邊商品
A8: 舞台劇 | B8: =B7 -> 周邊商品
A9: 數位典藏 | B9: =A9 -> 數位典藏

Sheet 管道定義
A1: Row Labels | C1: (empty) | D1: 大/中/小 | E1: 管道分類
A2: n/a | B2: ERP | D2: =C2&B2&A2 -> ERPn/a | E2: -
A3: TM | B3: CRM | D3: =C3&B3&A3 -> CRMTM | E3: TM
A4: 其他 | B4: CRM | D4: =C4&B4&A4 -> CRM其他 | E4: 其他
A5: 官網 | B5: CRM | D5: =C5&B5&A5 -> CRM官網 | E5: 官網
A6: 網站 | B6: SHOPLINE | D6: =C6&B6&A6 -> SHOPLINE網站 | E6: 官網
A7: 團購 | B7: CRM | D7: =C7&B7&A7 -> CRM團購 | E7: 團購
A8: 團購 | B8: CRM | D8: =C8&B8&A8 -> CRM團購 | E8: 團購
A9: 團購 | B9: CRM | D9: =C9&B9&A9 -> CRM團購 | E9: 團購
A10: 團購 | B10: CRM | D10: =C10&B10&A10 -> CRM團購 | E10: 團購
A11: 團購 | B11: CRM | D11: =C11&B11&A11 -> CRM團購 | E11: 團購
A12: 團購 | B12: CRM | D12: =C12&B12&A12 -> CRM團購 | E12: 團購
A13: 團購 | B13: CRM | D13: =C13&B13&A13 -> CRM團購 | E13: 團購
... A52: 團購 | B52: CRM | D52: =C52&B52&A52 -> CRM團購 | E52: 團購
B53: SHOPLINE | D53: =C53&B53&A53 -> SHOPLINE | E53: 團購
A54: 團購 | B54: CRM | D54: =C54&B54&A54 -> CRM團購 | E54: 團購
A55: 團購 | B55: SHOPLINE | D55: =C55&B55&A55 -> SHOPLINE團購 | E55: 團購
A56: 團購 | B56: SHOPLINE | D56: =C56&B56&A56 -> SHOPLINE團購 | E56: 團購
A57: 團購 | B57: CRM | D57: =C57&B57&A57 -> CRM團購 | E57: 團購
A58: 其他 | B58: CRM | D58: =C58&B58&A58 -> CRM其他 | E58: 其他
A59: 團購 | B59: SHOPLINE | D59: =C59&B59&A59 -> SHOPLINE團購 | E59: 團購
A60: 團購 | B60: CRM | D60: =C60&B60&A60 -> CRM團購 | E60: 團購
A61: 團購 | B61: SHOPLINE | D61: =C61&B61&A61 -> SHOPLINE團購 | E61: 團購
A62: 團購 | B62: SHOPLINE | D62: =C62&B62&A62 -> SHOPLINE團購 | E62: 團購
A63: 團購 | B63: SHOPLINE | D63: =C63&B63&A63 -> SHOPLINE團購 | E63: 團購
A64: 團購 | B64: SHOPLINE | D64: =C64&B64&A64 -> SHOPLINE團購 | E64: 團購
A65: 團購 | B65: CRM | D65: =C65&B65&A65 -> CRM團購 | E65: 團購
... A92: 團購 | B92: CRM | D92: =C92&B92&A92 -> CRM團購 | E92: 團購
B93: SHOPLINE | D93: =C93&B93&A93 -> SHOPLINE | E93: 團購
A94: 授權 | B94: ERP | D94: =C94&B94&A94 -> ERP授權 | E94: 授權
A95: 團購 | B95: CRM | D95: =C95&B95&A95 -> CRM團購 | E95: 團購
A96: 團購 | B96: CRM | D96: =C96&B96&A96 -> CRM團購 | E96: 團購
A97: 經代銷 | B97: CRM | D97: =C97&B97&A97 -> CRM經代銷 | E97: 經代銷
A98: 團購 | B98: SHOPLINE | D98: =C98&B98&A98 -> SHOPLINE團購 | E98: 團購
A99: 授權 | B99: ERP | D99: =C99&B99&A99 -> ERP授權 | E99: 授權（樂園）
A100: 團購 | B100: CRM | D100: =C100&B100&A100 -> CRM團購 | E100: 團購
A101: 團購 | B101: CRM | D101: =C101&B101&A101 -> CRM團購 | E101: 團購
A102: 團購 | B102: SHOPLINE | D102: =C102&B102&A102 -> SHOPLINE團購 | E102: 團購
A103: 團購 | B103: CRM | D103: =C103&B103&A103 -> CRM團購 | E103: 團購
A104: 團購 | B104: CRM | D104: =C104&B104&A104 -> CRM團購 | E104: 團購
...

Sheet 學習商品(claude)
A1: 事業別 | B1: 商品編號 | C1: 商品名稱 | D1: 單價 | E1: 追加製作期_月 | F1: 首月銷售月份
A2: 學習商品 | B2: 20250FF00 | C2: 聰明左右腦 點讀大冒險套組 | D2: 2999 | E2: 6 | F2: 202603
A3: 學習商品 | B3: 20250FG00 | C3: 和巧虎一起學數學套組 | D3: 3200 | E3: 6 | F3: 202603
A4: 學習商品 | B4: 20250FE00 | C4: 巧虎雙語點讀圖鑑 | D4: 2399 | E4: 6 | F4: =_xlfn.XLOOKUP(B4,'[1]學習商品銷售(cube）'!$C:$C,'[1]學習商品銷售(cube）'!$B:$B,"") -> 202601
A5: 學習商品 | B5: 20230MY00 | C5: 和巧虎一起說英語Plus | D5: 4800 | E5: 6 | F5: =_xlfn.XLOOKUP(B5,'[1]學習商品銷售(cube）'!$C:$C,'[1]學習商品銷售(cube）'!$B:$B,"") -> 202407
A6: 學習商品 | B6: 20220MY00 | C6: 和巧虎一起說英語【進階版】 | D6: 4500 | E6: 6 | F6: =_xlfn.XLOOKUP(B6,'[1]學習商品銷售(cube）'!$C:$C,'[1]學習商品銷售(cube）'!$B:$B,"") -> 202404
A7: 學習商品 | B7: 20250FA00 | C7: 好情緒EQ X 品格人際套組 | D7: 2199 | E7: 6 | F7: =_xlfn.XLOOKUP(B7,'[1]學習商品銷售(cube）'!$C:$C,'[1]學習商品銷售(cube）'!$B:$B,"") -> 202505
A8: 學習商品 | B8: 20240FA00 | C8: 寶寶生活好習慣套組 | D8: 4299 | E8: 6 | F8: =_xlfn.XLOOKUP(B8,'[1]學習商品銷售(cube）'!$C:$C,'[1]學習商品銷售(cube）'!$B:$B,"") -> 202410
A9: 學習商品 | B9: 20240FM00 | C9: 和巧虎一起學-注音拼音套組（注音2.0） | D9: 3200 | E9: 6 | F9: =_xlfn.XLOOKUP(B9,'[1]學習商品銷售(cube）'!$C:$C,'[1]學習商品銷售(cube）'!$B:$B,"") -> 202411
A10: 學習商品 | B10: 20250FD00 | C10: 語彙表達‧智育學習套組 | D10: 4900 | E10: 6 | F10: =_xlfn.XLOOKUP(B10,'[1]學習商品銷售(cube）'!$C:$C,'[1]學習商品銷售(cube）'!$B:$B,"") -> 202510

Sheet 銷貨數(claude)
A1: =MAX(E1:ZZ1) -> 16 | D1: =COLUMN()-3 -> 1 | E1: =COLUMN()-3 -> 2 | F1: =IF(F3="","",COLUMN()-3) -> 3 | G1: =IF(G3="","",COLUMN()-3) -> 4 | H1: =IF(H3="","",COLUMN()-3) -> 5 | I1: =IF(I3="","",COLUMN()-3) -> 6 | J1: =IF(J3="","",COLUMN()-3) -> 7 | K1: =IF(K3="","",COLUMN()-3) -> 8 | L1: =IF(L3="","",COLUMN()-3) -> 9 | M1: =IF(M3="","",COLUMN()-3) -> 10 | ... AH1: =IF(AH3="","",COLUMN()-3) | AI1: =IF(AI3="","",COLUMN()-5) | AJ1: =IF(AJ3="","",COLUMN()-5) | AK1: =IF(AK3="","",COLUMN()-5) | AL1: =IF(AL3="","",COLUMN()-5) | AM1: =IF(AM3="","",COLUMN()-5) | AN1: =IF(AN3="","",COLUMN()-5) | AO1: =IF(AO3="","",COLUMN()-5) | AP1: =IF(AP3="","",COLUMN()-5) | ... BK1: =IF(BK3="","",COLUMN()-5)
A2: 銷貨_銷貨數量 | H2: 銷貨年月
A3: 事業別 | B3: 管道大類 | C3: 管道中類 | D3: 管道小類 | E3: 商品編號 | F3: 商品名稱 | G3: 商品單價 | H3: 202504 | I3: 202505 | J3: 202506 | K3: 202507 | L3: 202508 | M3: 202509 | N3: 202510 | O3: 202511 | P3: 202512 | Q3: 202601 | R3: 202602 | S3: 202603
A4: 學習商品 | B4: CRM | C4: TM | D4: - | E4: 20200FB00 | F4: 九九乘法偵探套組 | G4: 2500.00 | H4: 9
A5: 學習商品 | B5: CRM | C5: TM | D5: - | E5: 20220MY00 | F5: 和巧虎一起說英語套組進階版 | G5: 4500.00 | H5: 43 | I5: 36 | J5: 30 | K5: 22 | L5: 36 | M5: 47 | N5: 44 | O5: 36 | P5: 58 | Q5: 44
A6: 學習商品 | B6: CRM | C6: TM | D6: - | E6: 20230MY00 | F6: 和巧虎一起說英語Plus | G6: 4800.00 | H6: 76 | I6: 91 | J6: 38 | K6: 45 | L6: 69 | M6: 74 | N6: 57 | O6: 55 | P6: 52 | Q6: 44
A7: 學習商品 | B7: CRM | C7: TM | D7: - | E7: 20240FA00 | F7: 寶寶生活好習慣學習套組A | G7: 4299.00 | H7: 93 | I7: 69 | J7: 44 | K7: 31 | L7: 36 | M7: 21 | N7: 29 | O7: 29 | P7: 32 | Q7: 29
A8: 學習商品 | B8: CRM | C8: TM | D8: - | E8: 20240FA11 | F8: 爸媽報報 | G8: 600.00 | K8: 1
A9: 學習商品 | B9: CRM | C9: TM | D9: - | E9: 20240FC00 | F9: 點讀巧比思考力遊戲組 | G9: 1999.00 | H9: 143 | I9: 102 | J9: 104 | K9: 90 | L9: 92 | M9: 75 | N9: 47 | O9: 50 | P9: 72 | Q9: 1
A10: 學習商品 | B10: CRM | C10: TM | D10: - | E10: 20240FC12 | F10: 點讀巧比思考力遊戲組使用說明書 | G10: 300.00 | I10: 2
A11: 學習商品 | B11: CRM | C11: TM | D11: - | E11: 20240FM00 | F11: 注音套組2.0 | G11: 3200.00 | H11: 80 | I11: 63 | J11: 64 | K11: 63 | L11: 64 | M11: 77 | N11: 109 | O11: 68 | P11: 83 | Q11: 89
A12: 學習商品 | B12: CRM | C12: TM | D12: - | E12: 20250FA00 | F12: 好情緒EQ X 品格人際套組 | G12: 2199.00 | I12: 344 | J12: 337 | K12: 215 | L12: 191 | M12: 2 | N12: 115 | O12: 109 | P12: 97 | Q12: 88
A13: 學習商品 | B13: CRM | C13: TM | D13: - | E13: 20250FB01 | F13: 閱讀橋樑書系列1_IQ184偵團 | G13: 900.00 | K13: 1 | O13: 1 | Q13: 1
A14: 學習商品 | B14: CRM | C14: TM | D14: - | E14: 20250FB01 | F14: 閱讀橋樑書系列1_IQ184偵團 | G14: 999.00 | J14: 1 | K14: 3 | L14: 1 | M14: 2 | O14: 2 | Q14: 1
A15: 學習商品 | B15: CRM | C15: TM | D15: - | E15: 20250FB02 | F15: 閱讀橋樑書系列2_黑腹貓華生 | G15: 900.00 | Q15: 1
A16: 學習商品 | B16: CRM | C16: TM | D16: - | E16: 20250FB02 | F16: 閱讀橋樑書系列2_黑腹貓華生 | G16: 999.00 | J16: 1
A17: 學習商品 | B17: CRM | C17: TM | D17: - | E17: 20250FC02 | F17: 精選世界名著系列2_愛與成長 | G17: 1250.00 | N17: 1
A18: 學習商品 | B18: CRM | C18: TM | D18: - | E18: 20250FD00 | F18: 語彙表達‧智育學習套組 | G18: 4900.00 | N18: 136 | O18: 102 | P18: 74 | Q18: 72
A19: 學習商品 | B19: CRM | C19: TM | D19: - | E19: 20250FD01 | F19: 巧虎收納袋 | G19: 299.00 | N19: 5 | O19: 3 | P19: 4 | Q19: 4
A20: 學習商品 | B20: CRM | C20: TM | D20: - | E20: 20250FD14 | F20: 語彙表達‧ 智育學習套組-說明書 | G20: 1000.00 | P20: 1
A21: 學習商品 | B21: CRM | C21: TM | D21: - | E21: 20250FE00 | F21: 巧虎雙語點讀圖鑑 | G21: 2399.00 | Q21: 148
A22: 學習商品 | B22: CRM | C22: TM | D22: - | E22: 20250FXAB | F22: 巧連智精選世界名著1-3系列 | G22: 3300.00 | J22: 11 | K22: 25 | L22: 6 | M22: 2 | N22: 5 | O22: 6 | P22: 3 | Q22: 5
A23: 學習商品 | B23: CRM | C23: TM | D23: - | E23: 20250FXAC | F23: 巧連智閱讀橋樑書1-3系列 | G23: 2400.00 | J23: 21 | K23: 56 | L23: 28 | M23: 13 | N23: 13 | O23: 16 | P23: 10 | Q23: 12
A24: 學習商品 | B24: CRM | C24: TM | D24: - | E24: 20250FXAD | F24: 卡哩村超能力學園系列3 | G24: 900.00 | K24: 1 | O24: 1
A25: 學習商品 | B25: CRM | C25: TM | D25: - | E25: 20250FXAD | F25: 卡哩村超能力學園系列3 | G25: 999.00 | M25: 2
A26: 學習商品 | B26: CRM | C26: TM | D26: 電銷管道加贈禮 | E26: 20220MY00 | F26: 和巧虎一起說英語套組進階版 | G26: 4500.00 | K26: 1
A27: 學習商品 | B27: CRM | C27: TM | D27: 電銷管道加贈禮 | E27: 20240FC00 | F27: 點讀巧比思考力遊戲組 | G27: 1999.00 | J27: 2
A28: 學習商品 | B28: CRM | C28: TM | D28: 電銷管道加贈禮 | E28: 20250FA00 | F28: 好情緒EQ X 品格人際套組 | G28: 2199.00 | I28: 1 | J28: 4 | K28: 2
A29: 學習商品 | B29: CRM | C29: TM | D29: 倍樂生訂戶會員 | E29: 20220MY00 | F29: 和巧虎一起說英語套組進階版 | G29: 4500.00 | R29: 28 | S29: 34
A30: 學習商品 | B30: CRM | C30: TM | D30: 倍樂生訂戶會員 | E30: 20230MY00 | F30: 和巧虎一起說英語Plus | G30: 4800.00 | R30: 25 | S30: 46
A31: 學習商品 | B31: CRM | C31: TM | D31: 倍樂生訂戶會員 | E31: 20240FA00 | F31: 寶寶生活好習慣學習套組A | G31: 4299.00 | R31: 22 | S31: 32
A32: 學習商品 | B32: CRM | C32: TM | D32: 倍樂生訂戶會員 | E32: 20240FC00 | F32: 點讀巧比思考力遊戲組 | G32: 1999.00 | R32: 1
A33: 學習商品 | B33: CRM | C33: TM | D33: 倍樂生訂戶會員 | E33: 20240FM00 | F33: 注音套組2.0 | G33: 3200.00 | R33: 46 | S33: 71
A34: 學習商品 | B34: CRM | C34: TM | D34: 倍樂生訂戶會員 | E34: 20250FA00 | F34: 好情緒EQ X 品格人際套組 | G34: 2199.00 | R34: 51 | S34: 72
A35: 學習商品 | B35: CRM | C35: TM | D35: 倍樂生訂戶會員 | E35: 20250FD00 | F35: 語彙表達‧智育學習套組 | G35: 4900.00 | R35: 33 | S35: 58
A36: 學習商品 | B36: CRM | C36: TM | D36: 倍樂生訂戶會員 | E36: 20250FD01 | F36: 巧虎收納袋 | G36: 299.00 | S36: 1
A37: 學習商品 | B37: CRM | C37: TM | D37: 倍樂生訂戶會員 | E37: 20250FE00 | F37: 巧虎雙語點讀圖鑑 | G37: 2399.00 | R37: 93 | S37: 74
A38: 學習商品 | B38: CRM | C38: TM | D38: 倍樂生訂戶會員 | E38: 20250FF00 | F38: 聰明左右腦 點讀大冒險套組 | G38: 2999.00 | S38: 214
A39: 學習商品 | B39: CRM | C39: TM | D39: 倍樂生訂戶會員 | E39: 20250FG00 | F39: 和巧虎一起學數學套組 | G39: 3200.00 | S39: 268
A40: 學習商品 | B40: CRM | C40: TM | D40: 倍樂生訂戶會員 | E40: 20250FXAB | F40: 巧連智精選世界名著1-3系列 | G40: 3300.00 | R40: 5 | S40: 3
...

Sheet 在庫(claude)
D1: 日商倍樂生股份有限公司台北分公司
D2: 庫存明細表
A3: ='[2]庫存明細表(INVR18)'!A3 -> 製表日期: 115/05/11 | B3: ='[2]庫存明細表(INVR18)'!B3 -> 0 | C3: ='[2]庫存明細表(INVR18)'!C3 -> 0 | D3: ='[2]庫存明細表(INVR18)'!D3 -> 資料日期: 115/05/11 | E3: ='[2]庫存明細表(INVR18)'!E3 -> 0 | F3: ='[2]庫存明細表(INVR18)'!F3 -> 0 | G3: ='[2]庫存明細表(INVR18)'!G3 -> 第 1 頁
A4: ='[2]庫存明細表(INVR18)'!A4 -> 品號 | B4: ='[2]庫存明細表(INVR18)'!B4 -> 品名 | C4: ='[2]庫存明細表(INVR18)'!C4 -> 單位成本 | D4: ='[2]庫存明細表(INVR18)'!D4 -> 庫存數量 | E4: ='[2]庫存明細表(INVR18)'!E4 -> 庫存金額 | F4: ='[2]庫存明細表(INVR18)'!F4 -> 庫別 | G4: ='[2]庫存明細表(INVR18)'!G4 -> 庫別名稱
A5: ='[2]庫存明細表(INVR18)'!A5 -> 20162C605 | B5: ='[2]庫存明細表(INVR18)'!B5 -> 1605月幼幼版彩色形狀建築師 | C5: ='[2]庫存明細表(INVR18)'!C5 -> 58.83 | D5: ='[2]庫存明細表(INVR18)'!D5 -> 6 | E5: ='[2]庫存明細表(INVR18)'!E5 -> 353 | F5: ='[2]庫存明細表(INVR18)'!F5 -> 0 | G5: ='[2]庫存明細表(INVR18)'!G5 -> 0
A6: ='[2]庫存明細表(INVR18)'!A6 -> 2017AC109 | B6: ='[2]庫存明細表(INVR18)'!B6 -> 繪本-早安！起床了！ | C6: ='[2]庫存明細表(INVR18)'!C6 -> 57.8 | D6: ='[2]庫存明細表(INVR18)'!D6 -> 5 | E6: ='[2]庫存明細表(INVR18)'!E6 -> 289 | F6: ='[2]庫存明細表(INVR18)'!F6 -> 0 | G6: ='[2]庫存明細表(INVR18)'!G6 -> 0
A7: ='[2]庫存明細表(INVR18)'!A7 -> 2017AC110 | B7: ='[2]庫存明細表(INVR18)'!B7 -> 繪本-這是什麼？身體圖鑑 | C7: ='[2]庫存明細表(INVR18)'!C7 -> 33.41 | D7: ='[2]庫存明細表(INVR18)'!D7 -> 183 | E7: ='[2]庫存明細表(INVR18)'!E7 -> 6114 | F7: ='[2]庫存明細表(INVR18)'!F7 -> 0 | G7: ='[2]庫存明細表(INVR18)'!G7 -> 0
A8: ='[2]庫存明細表(INVR18)'!A8 -> 2017AC111 | B8: ='[2]庫存明細表(INVR18)'!B8 -> 繪本-這是什麼？食物與生活用品 | C8: ='[2]庫存明細表(INVR18)'!C8 -> 48.25 | D8: ='[2]庫存明細表(INVR18)'!D8 -> 187 | E8: ='[2]庫存明細表(INVR18)'!E8 -> 9023 | F8: ='[2]庫存明細表(INVR18)'!F8 -> 0 | G8: ='[2]庫存明細表(INVR18)'!G8 -> 0
A9: ='[2]庫存明細表(INVR18)'!A9 -> 2017AC113 | B9: ='[2]庫存明細表(INVR18)'!B9 -> 繪本-我會大聲說有 | C9: ='[2]庫存明細表(INVR18)'!C9 -> 46.55 | D9: ='[2]庫存明細表(INVR18)'!D9 -> 64 | E9: ='[2]庫存明細表(INVR18)'!E9 -> 2979 | F9: ='[2]庫存明細表(INVR18)'!F9 -> 0 | G9: ='[2]庫存明細表(INVR18)'!G9 -> 0
A10: ='[2]庫存明細表(INVR18)'!A10 -> 2017AC121 | B10: ='[2]庫存明細表(INVR18)'!B10 -> 繪本-一起分享好開心 | C10: ='[2]庫存明細表(INVR18)'!C10 -> 52.42 | D10: ='[2]庫存明細表(INVR18)'!D10 -> 24 | E10: ='[2]庫存明細表(INVR18)'!E10 -> 1258 | F10: ='[2]庫存明細表(INVR18)'!F10 -> 0 | G10: ='[2]庫存明細表(INVR18)'!G10 -> 0
A11: ='[2]庫存明細表(INVR18)'!A11 -> 2017AC611 | B11: ='[2]庫存明細表(INVR18)'!B11 -> 11月齡寶寶推推樂 | C11: ='[2]庫存明細表(INVR18)'!C11 -> 51 | D11: ='[2]庫存明細表(INVR18)'!D11 -> 1 | E11: ='[2]庫存明細表(INVR18)'!E11 -> 51 | F11: ='[2]庫存明細表(INVR18)'!F11 -> 0 | G11: ='[2]庫存明細表(INVR18)'!G11 -> 0
A12: ='[2]庫存明細表(INVR18)'!A12 -> 20184C603 | B12: ='[2]庫存明細表(INVR18)'!B12 -> 桌遊-恐龍世界大挑戰 | C12: ='[2]庫存明細表(INVR18)'!C12 -> 45.94 | D12: ='[2]庫存明細表(INVR18)'!D12 -> 33 | E12: ='[2]庫存明細表(INVR18)'!E12 -> 1516 | F12: ='[2]庫存明細表(INVR18)'!F12 -> 0 | G12: ='[2]庫存明細表(INVR18)'!G12 -> 0
A13: ='[2]庫存明細表(INVR18)'!A13 -> 2018AC812 | B13: ='[2]庫存明細表(INVR18)'!B13 -> 巧虎手偶 | C13: ='[2]庫存明細表(INVR18)'!C13 -> 73.5 | D13: ='[2]庫存明細表(INVR18)'!D13 -> 1528 | E13: ='[2]庫存明細表(INVR18)'!E13 -> 112306 | F13: ='[2]庫存明細表(INVR18)'!F13 -> 0 | G13: ='[2]庫存明細表(INVR18)'!G13 -> 0
A14: ='[2]庫存明細表(INVR18)'!A14 -> 2018AC812-L | B14: ='[2]庫存明細表(INVR18)'!B14 -> 巧虎手偶說明信 | C14: ='[2]庫存明細表(INVR18)'!C14 -> 0 | D14: ='[2]庫存明細表(INVR18)'!D14 -> 1840 | E14: ='[2]庫存明細表(INVR18)'!E14 -> 0 | F14: ='[2]庫存明細表(INVR18)'!F14 -> 0 | G14: ='[2]庫存明細表(INVR18)'!G14 -> 0
... A791: ='[2]庫存明細表(INVR18)'!A791 -> 0 | B791: ='[2]庫存明細表(INVR18)'!B791 -> 0 | C791: ='[2]庫存明細表(INVR18)'!C791 -> 0 | D791: ='[2]庫存明細表(INVR18)'!D791 -> 0 | E791: ='[2]庫存明細表(INVR18)'!E791 -> 0 | F791: ='[2]庫存明細表(INVR18)'!F791 -> 0 | G791: ='[2]庫存明細表(INVR18)'!G791 -> 0

Sheet 銷貨數 (總數)(claude)
A1: =MAX(E1:ZZ1) -> 16 | D1: =IF(D3="","",COLUMN()) -> 4 | E1: =IF(E3="","",COLUMN()) -> 5 | F1: =IF(F3="","",COLUMN()) -> 6 | G1: =IF(G3="","",COLUMN()) -> 7 | H1: =IF(H3="","",COLUMN()) -> 8 | I1: =IF(I3="","",COLUMN()) -> 9 | J1: =IF(J3="","",COLUMN()) -> 10 | K1: =IF(K3="","",COLUMN()) -> 11 | ... BC1: =IF(BC3="","",COLUMN()) | BD1: =IF(BD3="","",COLUMN()-5) | BE1: =IF(BE3="","",COLUMN()-5) | BF1: =IF(BF3="","",COLUMN()-5) | BG1: =IF(BG3="","",COLUMN()-5) | BH1: =IF(BH3="","",COLUMN()-5) | BI1: =IF(BI3="","",COLUMN()-5) | BJ1: =IF(BJ3="","",COLUMN()-5) | BK1: =IF(BK3="","",COLUMN()-5)
A2: 銷貨_銷貨數量 | E2: 銷貨年月
A3: 事業別 | B3: 商品編號 | C3: 商品名稱 | D3: 商品單價 | E3: 202504 | F3: 202505 | G3: 202506 | H3: 202507 | I3: 202508 | J3: 202509 | K3: 202510 | L3: 202511 | M3: 202512 | N3: 202601 | O3: 202602 | P3: 202603
A4: 學習商品 | B4: 20200FB00 | C4: 九九乘法偵探套組 | D4: 2500.00 | E4: 9
A5: 學習商品 | B5: 2021MPB10 | C5: 巧虎水果形狀蛋糕組 | D5: 110.00 | E5: 150
A6: 學習商品 | B6: 20220MY00 | C6: 和巧虎一起說英語套組進階版 | D6: 4005.97 | I6: 24
A7: 學習商品 | B7: 20220MY00 | C7: 和巧虎一起說英語套組進階版 | D7: 4228.08 | O7: 15
A8: 學習商品 | B8: 20220MY00 | C8: 和巧虎一起說英語套組進階版 | D8: 4500.00 | E8: 72 | F8: 104 | G8: 49 | H8: 53 | I8: 58 | J8: 58 | K8: 67 | L8: 64 | M8: 79 | N8: 57 | O8: 34 | P8: 73
A9: 學習商品 | B9: 20230MY00 | C9: 和巧虎一起說英語Plus | D9: 4273.04 | I9: 25
A10: 學習商品 | B10: 20230MY00 | C10: 和巧虎一起說英語Plus | D10: 4509.95 | O10: 25
A11: 學習商品 | B11: 20230MY00 | C11: 和巧虎一起說英語Plus | D11: 4800.00 | E11: 141 | F11: 284 | G11: 107 | H11: 128 | I11: 146 | J11: 131 | K11: 147 | L11: 188 | M11: 106 | N11: 93 | O11: 52 | P11: 151
A12: 學習商品 | B12: 2023MPB01 | C12: 巧虎DIY英語城堡 | D12: 158.00 | E12: 200
A13: 學習商品 | B13: 20240FA00 | C13: 寶寶生活好習慣學習套組A | D13: 1499.00 | N13: 1
A14: 學習商品 | B14: 20240FA00 | C14: 寶寶生活好習慣學習套組A | D14: 2299.00 | I14: 2
A15: 學習商品 | B15: 20240FA00 | C15: 寶寶生活好習慣學習套組A | D15: 4039.11 | O15: 15
A16: 學習商品 | B16: 20240FA00 | C16: 寶寶生活好習慣學習套組A | D16: 4299.00 | E16: 190 | F16: 590 | G16: 155 | H16: 79 | I16: 122 | J16: 111 | K16: 125 | L16: 162 | M16: 90 | N16: 117 | O16: 80 | P16: 119
A17: 學習商品 | B17: 20240FA00 | C17: 寶寶生活好習慣學習套組A | D17: 4498.00 | L17: 2
A18: 學習商品 | B18: 20240FA00 | C18: 寶寶生活好習慣學習套組A | D18: 4598.00 | E18: 11 | F18: 14 | G18: 11 | H18: 9 | I18: 2
A19: 學習商品 | B19: 20240FA11 | C19: 爸媽報報 | D19: 600.00 | H19: 1
A20: 學習商品 | B20: 20240FC00 | C20: 點讀巧比思考力遊戲組 | D20: 1799.39 | I20: 4
A21: 學習商品 | B21: 20240FC00 | C21: 點讀巧比思考力遊戲組 | D21: 1899.16 | O21: 8
A22: 學習商品 | B22: 20240FC00 | C22: 點讀巧比思考力遊戲組 | D22: 1999.00 | E22: 310 | F22: 522 | G22: 285 | H22: 217 | I22: 232 | J22: 247 | K22: 236 | L22: 368 | M22: 257 | N22: 1 | O22: 1
A23: 學習商品 | B23: 20240FC00 | C23: 點讀巧比思考力遊戲組 | D23: 3999.00 | M23: 2 | N23: 3
A24: 學習商品 | B24: 20240FC12 | C24: 點讀巧比思考力遊戲組使用說明書 | D24: 300.00 | F24: 2
A25: 學習商品 | B25: 20240FM00 | C25: 注音套組2.0 | D25: 3200.00 | E25: 159 | F25: 562 | G25: 156 | H25: 126 | I25: 123 | J25: 127 | K25: 196 | L25: 130 | M25: 124 | N25: 143 | O25: 80 | P25: 174
A26: 學習商品 | B26: 20250FA00 | C26: 好情緒EQ X 品格人際套組 | D26: 1935.62 | I26: 72
A27: 學習商品 | B27: 20250FA00 | C27: 好情緒EQ X 品格人際套組 | D27: 2199.00 | F27: 1322 | G27: 621 | H27: 501 | I27: 412 | J27: 39 | K27: 323 | L27: 274 | M27: 208 | N27: 235 | O27: 136 | P27: 264
A28: 學習商品 | B28: 20250FB01 | C28: 閱讀橋樑書系列1_IQ184偵團 | D28: 800.00 | J28: 2 | L28: 1
A29: 學習商品 | B29: 20250FB01 | C29: 閱讀橋樑書系列1_IQ184偵團 | D29: 900.00 | H29: 1 | L29: 1 | N29: 1
A30: 學習商品 | B30: 20250FB01 | C30: 閱讀橋樑書系列1_IQ184偵團 | D30: 999.00 | G30: 2 | H30: 3 | I30: 2 | J30: 6 | K30: 2 | L30: 3 | M30: 1 | N30: 7 | P30: 6
A31: 學習商品 | B31: 20250FB01 | C31: 閱讀橋樑書系列1_IQ184偵團 | D31: 2400.00 | G31: 3 | H31: 1 | I31: 2
A32: 學習商品 | B32: 20250FB02 | C32: 閱讀橋樑書系列2_黑腹貓華生 | D32: 800.00 | J32: 2 | L32: 1
A33: 學習商品 | B33: 20250FB02 | C33: 閱讀橋樑書系列2_黑腹貓華生 | D33: 900.00 | N33: 1
A34: 學習商品 | B34: 20250FB02 | C34: 閱讀橋樑書系列2_黑腹貓華生 | D34: 999.00 | G34: 1 | H34: 3 | I34: 1 | J34: 1 | N34: 2
A35: 學習商品 | B35: 20250FB03 | C35: 閱讀橋樑書系列3_卡哩村超能力學園 | D35: 800.00 | J35: 2 | L35: 1
A36: 學習商品 | B36: 20250FC01 | C36: 精選世界名著系列1_勇氣與挑戰 | D36: 1100.00 | J36: 1 | L36: 1 | O36: 1
A37: 學習商品 | B37: 20250FC01 | C37: 精選世界名著系列1_勇氣與挑戰 | D37: 1250.00 | H37: 2 | I37: 1 | O37: 1 | P37: 3
A38: 學習商品 | B38: 20250FC01 | C38: 精選世界名著系列1_勇氣與挑戰 | D38: 3300.00 | H38: 2
A39: 學習商品 | B39: 20250FC02 | C39: 精選世界名著系列2_愛與成長 | D39: 1100.00 | J39: 1 | L39: 1 | O39: 1
A40: 學習商品 | B40: 20250FC02 | C40: 精選世界名著系列2_愛與成長 | D40: 1250.00 | G40: 1 | K40: 1 | O40: 1
...

Sheet 工作表1

Sheet DPCache_工作表1
A1: CRM | B1: TM | C1: -
A2: CRM | B2: TM | C2: -
A3: CRM | B3: TM | C3: -
A4: CRM | B4: TM | C4: -
A5: CRM | B5: TM | C5: -
A6: CRM | B6: TM | C6: -
A7: CRM | B7: TM | C7: -
A8: CRM | B8: TM | C8: -
A9: CRM | B9: TM | C9: -
A10: CRM | B10: TM | C10: -
A11: CRM | B11: TM | C11: -
A12: CRM | B12: TM | C12: -
... A4552: CRM | B4552: TM | C4552: -

Sheet DPCache_工作表1 -1
A1: CRM | B1: TM | C1: -
A2: CRM | B2: TM | C2: -
A3: CRM | B3: TM | C3: -
A4: CRM | B4: TM | C4: -
A5: CRM | B5: TM | C5: -
A6: CRM | B6: TM | C6: -
A7: CRM | B7: TM | C7: -
A8: CRM | B8: TM | C8: -
A9: CRM | B9: TM | C9: -
A10: CRM | B10: TM | C10: -
A11: CRM | B11: TM | C11: -
A12: CRM | B12: TM | C12: -
... A4552: CRM | B4552: TM | C4552: -
